2024-07-29 18:16:04,487 - app - ERROR - 内部服务器错误: name 'form_data' is not defined
2024-07-29 18:21:57,394 - app - ERROR - 内部服务器错误: A secret key is required to use CSRF.
2024-07-29 18:21:58,257 - app - ERROR - 内部服务器错误: A secret key is required to use CSRF.
2024-07-29 18:22:11,272 - app - ERROR - 内部服务器错误: A secret key is required to use CSRF.
2024-07-30 17:28:54,874 - app - ERROR - 内部服务器错误: 没有这个数据库
2024-07-30 19:01:25,612 - app - ERROR - 获取平台信息失败: (pymysql.err.OperationalError) (1049, "Unknown database 'marketing'")
(Background on this error at: https://sqlalche.me/e/20/e3q8)
2024-07-30 23:49:41,464 - app - ERROR - 内部服务器错误: "['id', 'user_id', '地区', '国家编码', '评级', '红人全名', '红人主页地址', '红人头像地址', '粉丝数量', '平均点赞数量', '平均评论数量', '平均播放量', '平均参与率', '联系方式1', '地址信息1', '标签功能1', '联系方式2', '地址信息2', '标签功能2', '联系方式3', '地址信息3', '标签功能3'] not in index"
2024-07-30 23:55:57,755 - app - ERROR - 内部服务器错误: "['id', 'user_id', '地区', '评级', '红人全名', '红人主页地址', '红人头像地址', '粉丝数量', '平均点赞数量', '平均评论数量', '平均播放量', '平均参与率', '联系方式1', '地址信息1', '标签功能1', '联系方式2', '地址信息2', '标签功能2', '联系方式3', '地址信息3', '标签功能3'] not in index"
2024-07-31 00:07:57,504 - app - ERROR - 内部服务器错误: "['id', 'user_id', '地区', '评级', '红人全名', '红人主页地址', '红人头像地址', '粉丝数量', '平均点赞数量', '平均评论数量', '平均播放量', '平均参与率', '联系方式1', '联系方式2', '联系方式3'] not in index"
2024-07-31 10:46:34,161 - app - ERROR - 内部服务器错误: (pymysql.err.OperationalError) (1054, "Unknown column '邮箱' in 'field list'")
[SQL: INSERT INTO celebrity_profile (`平台`, `红人名称`, `邮箱`, `WhatsApp`, `Discord`, `地址信息1`, `地址信息2`, `地址信息3`, `标签功能1`, `标签功能2`, `标签功能3`, `国家`, `国家编码`, `更新日期`) VALUES (%(平台)s, %(红人名称)s, %(邮箱)s, %(WhatsApp)s, %(Discord)s, %(地址信息1)s, %(地址信息2)s, %(地址信息3)s, %(标签功能1)s, %(标签功能2)s, %(标签功能3)s, %(国家)s, %(国家编码)s, %(更新日期)s)]
[parameters: {'平台': 'ins', '红人名称': 'jolin_cai', '邮箱': '', 'WhatsApp': '', 'Discord': '', '地址信息1': '', '地址信息2': '', '地址信息3': '', '标签功能1': '', '标签功能2': '', '标签功能3': 'test', '国家': '', '国家编码': '', '更新日期': datetime.date(2024, 7, 31)}]
(Background on this error at: https://sqlalche.me/e/20/e3q8)
2024-08-05 15:43:36,599 - app - ERROR - 获取平台信息失败: (pymysql.err.ProgrammingError) (1146, "Table 'marketing.celebrity_profile' doesn't exist")
[SQL: SELECT DISTINCT 平台 FROM celebrity_profile]
(Background on this error at: https://sqlalche.me/e/20/f405)
2024-08-05 15:44:04,183 - app - ERROR - 获取平台信息失败: (pymysql.err.ProgrammingError) (1146, "Table 'marketing.celebrity_profile' doesn't exist")
[SQL: SELECT DISTINCT 平台 FROM celebrity_profile]
(Background on this error at: https://sqlalche.me/e/20/f405)
2024-08-05 15:44:51,970 - app - ERROR - 获取平台信息失败: (pymysql.err.ProgrammingError) (1146, "Table 'marketing.celebrity_profile' doesn't exist")
[SQL: SELECT DISTINCT 平台 FROM celebrity_profile]
(Background on this error at: https://sqlalche.me/e/20/f405)
2024-08-09 10:40:03,284 - app - ERROR - Exception on /notice/spider [POST]
Traceback (most recent call last):
  File "D:\wzhData\app\conda3\envs\DataAnalysis_39\lib\site-packages\flask\app.py", line 1473, in wsgi_app
    response = self.full_dispatch_request()
  File "D:\wzhData\app\conda3\envs\DataAnalysis_39\lib\site-packages\flask\app.py", line 882, in full_dispatch_request
    rv = self.handle_user_exception(e)
  File "D:\wzhData\app\conda3\envs\DataAnalysis_39\lib\site-packages\flask_cors\extension.py", line 178, in wrapped_function
    return cors_after_request(app.make_response(f(*args, **kwargs)))
  File "D:\wzhData\app\conda3\envs\DataAnalysis_39\lib\site-packages\flask\app.py", line 880, in full_dispatch_request
    rv = self.dispatch_request()
  File "D:\wzhData\app\conda3\envs\DataAnalysis_39\lib\site-packages\flask\app.py", line 865, in dispatch_request
    return self.ensure_sync(self.view_functions[rule.endpoint])(**view_args)  # type: ignore[no-any-return]
  File "D:\wzhData\BaiduSyncdisk\project\python\Influencer_Data_Management_System\spider\spider_notice.py", line 86, in post_spider_notice
    isSuccess, last_message = spider_notice.get_finish_notice(return_id)
  File "D:\wzhData\BaiduSyncdisk\project\python\Influencer_Data_Management_System\spider\spider_notice.py", line 69, in get_finish_notice
    self.clean_id_notice(_id)
  File "D:\wzhData\BaiduSyncdisk\project\python\Influencer_Data_Management_System\spider\spider_notice.py", line 38, in clean_id_notice
    del self.notice_info[_id]
KeyError: '5360c30f-ac73-42cf-bb6e-50df756fc449'
2024-08-09 10:40:08,288 - app - ERROR - Exception on /notice/spider [POST]
Traceback (most recent call last):
  File "D:\wzhData\app\conda3\envs\DataAnalysis_39\lib\site-packages\flask\app.py", line 1473, in wsgi_app
    response = self.full_dispatch_request()
  File "D:\wzhData\app\conda3\envs\DataAnalysis_39\lib\site-packages\flask\app.py", line 882, in full_dispatch_request
    rv = self.handle_user_exception(e)
  File "D:\wzhData\app\conda3\envs\DataAnalysis_39\lib\site-packages\flask_cors\extension.py", line 178, in wrapped_function
    return cors_after_request(app.make_response(f(*args, **kwargs)))
  File "D:\wzhData\app\conda3\envs\DataAnalysis_39\lib\site-packages\flask\app.py", line 880, in full_dispatch_request
    rv = self.dispatch_request()
  File "D:\wzhData\app\conda3\envs\DataAnalysis_39\lib\site-packages\flask\app.py", line 865, in dispatch_request
    return self.ensure_sync(self.view_functions[rule.endpoint])(**view_args)  # type: ignore[no-any-return]
  File "D:\wzhData\BaiduSyncdisk\project\python\Influencer_Data_Management_System\spider\spider_notice.py", line 86, in post_spider_notice
    isSuccess, last_message = spider_notice.get_finish_notice(return_id)
  File "D:\wzhData\BaiduSyncdisk\project\python\Influencer_Data_Management_System\spider\spider_notice.py", line 69, in get_finish_notice
    self.clean_id_notice(_id)
  File "D:\wzhData\BaiduSyncdisk\project\python\Influencer_Data_Management_System\spider\spider_notice.py", line 38, in clean_id_notice
    del self.notice_info[_id]
KeyError: '5360c30f-ac73-42cf-bb6e-50df756fc449'
2024-08-09 10:41:48,735 - app - ERROR - Exception on /notice/spider [POST]
Traceback (most recent call last):
  File "D:\wzhData\app\conda3\envs\DataAnalysis_39\lib\site-packages\flask\app.py", line 1473, in wsgi_app
    response = self.full_dispatch_request()
  File "D:\wzhData\app\conda3\envs\DataAnalysis_39\lib\site-packages\flask\app.py", line 882, in full_dispatch_request
    rv = self.handle_user_exception(e)
  File "D:\wzhData\app\conda3\envs\DataAnalysis_39\lib\site-packages\flask_cors\extension.py", line 178, in wrapped_function
    return cors_after_request(app.make_response(f(*args, **kwargs)))
  File "D:\wzhData\app\conda3\envs\DataAnalysis_39\lib\site-packages\flask\app.py", line 880, in full_dispatch_request
    rv = self.dispatch_request()
  File "D:\wzhData\app\conda3\envs\DataAnalysis_39\lib\site-packages\flask\app.py", line 865, in dispatch_request
    return self.ensure_sync(self.view_functions[rule.endpoint])(**view_args)  # type: ignore[no-any-return]
  File "D:\wzhData\BaiduSyncdisk\project\python\Influencer_Data_Management_System\spider\spider_notice.py", line 86, in post_spider_notice
    isSuccess, last_message = spider_notice.get_finish_notice(return_id)
  File "D:\wzhData\BaiduSyncdisk\project\python\Influencer_Data_Management_System\spider\spider_notice.py", line 60, in get_finish_notice
    work_info = self.work_id_time[_id]
KeyError: '5360c30f-ac73-42cf-bb6e-50df756fc449'
2024-08-09 10:41:53,283 - app - ERROR - Exception on /notice/spider [POST]
Traceback (most recent call last):
  File "D:\wzhData\app\conda3\envs\DataAnalysis_39\lib\site-packages\flask\app.py", line 1473, in wsgi_app
    response = self.full_dispatch_request()
  File "D:\wzhData\app\conda3\envs\DataAnalysis_39\lib\site-packages\flask\app.py", line 882, in full_dispatch_request
    rv = self.handle_user_exception(e)
  File "D:\wzhData\app\conda3\envs\DataAnalysis_39\lib\site-packages\flask_cors\extension.py", line 178, in wrapped_function
    return cors_after_request(app.make_response(f(*args, **kwargs)))
  File "D:\wzhData\app\conda3\envs\DataAnalysis_39\lib\site-packages\flask\app.py", line 880, in full_dispatch_request
    rv = self.dispatch_request()
  File "D:\wzhData\app\conda3\envs\DataAnalysis_39\lib\site-packages\flask\app.py", line 865, in dispatch_request
    return self.ensure_sync(self.view_functions[rule.endpoint])(**view_args)  # type: ignore[no-any-return]
  File "D:\wzhData\BaiduSyncdisk\project\python\Influencer_Data_Management_System\spider\spider_notice.py", line 86, in post_spider_notice
    isSuccess, last_message = spider_notice.get_finish_notice(return_id)
  File "D:\wzhData\BaiduSyncdisk\project\python\Influencer_Data_Management_System\spider\spider_notice.py", line 60, in get_finish_notice
    work_info = self.work_id_time[_id]
KeyError: '5360c30f-ac73-42cf-bb6e-50df756fc449'
2024-08-09 10:41:58,283 - app - ERROR - Exception on /notice/spider [POST]
Traceback (most recent call last):
  File "D:\wzhData\app\conda3\envs\DataAnalysis_39\lib\site-packages\flask\app.py", line 1473, in wsgi_app
    response = self.full_dispatch_request()
  File "D:\wzhData\app\conda3\envs\DataAnalysis_39\lib\site-packages\flask\app.py", line 882, in full_dispatch_request
    rv = self.handle_user_exception(e)
  File "D:\wzhData\app\conda3\envs\DataAnalysis_39\lib\site-packages\flask_cors\extension.py", line 178, in wrapped_function
    return cors_after_request(app.make_response(f(*args, **kwargs)))
  File "D:\wzhData\app\conda3\envs\DataAnalysis_39\lib\site-packages\flask\app.py", line 880, in full_dispatch_request
    rv = self.dispatch_request()
  File "D:\wzhData\app\conda3\envs\DataAnalysis_39\lib\site-packages\flask\app.py", line 865, in dispatch_request
    return self.ensure_sync(self.view_functions[rule.endpoint])(**view_args)  # type: ignore[no-any-return]
  File "D:\wzhData\BaiduSyncdisk\project\python\Influencer_Data_Management_System\spider\spider_notice.py", line 86, in post_spider_notice
    isSuccess, last_message = spider_notice.get_finish_notice(return_id)
  File "D:\wzhData\BaiduSyncdisk\project\python\Influencer_Data_Management_System\spider\spider_notice.py", line 60, in get_finish_notice
    work_info = self.work_id_time[_id]
KeyError: '5360c30f-ac73-42cf-bb6e-50df756fc449'
2024-08-09 10:43:50,282 - app - ERROR - Exception on /notice/spider [POST]
Traceback (most recent call last):
  File "D:\wzhData\app\conda3\envs\DataAnalysis_39\lib\site-packages\flask\app.py", line 1473, in wsgi_app
    response = self.full_dispatch_request()
  File "D:\wzhData\app\conda3\envs\DataAnalysis_39\lib\site-packages\flask\app.py", line 882, in full_dispatch_request
    rv = self.handle_user_exception(e)
  File "D:\wzhData\app\conda3\envs\DataAnalysis_39\lib\site-packages\flask_cors\extension.py", line 178, in wrapped_function
    return cors_after_request(app.make_response(f(*args, **kwargs)))
  File "D:\wzhData\app\conda3\envs\DataAnalysis_39\lib\site-packages\flask\app.py", line 880, in full_dispatch_request
    rv = self.dispatch_request()
  File "D:\wzhData\app\conda3\envs\DataAnalysis_39\lib\site-packages\flask\app.py", line 865, in dispatch_request
    return self.ensure_sync(self.view_functions[rule.endpoint])(**view_args)  # type: ignore[no-any-return]
  File "D:\wzhData\BaiduSyncdisk\project\python\Influencer_Data_Management_System\spider\spider_notice.py", line 89, in post_spider_notice
    isSuccess, last_message = spider_notice.get_finish_notice(return_id)
  File "D:\wzhData\BaiduSyncdisk\project\python\Influencer_Data_Management_System\spider\spider_notice.py", line 71, in get_finish_notice
    self.clean_id_notice(_id)
  File "D:\wzhData\BaiduSyncdisk\project\python\Influencer_Data_Management_System\spider\spider_notice.py", line 38, in clean_id_notice
    del self.notice_info[_id]
KeyError: '71063f53-f084-42d4-a4de-255c58f308f0'
2024-08-09 10:43:55,288 - app - ERROR - Exception on /notice/spider [POST]
Traceback (most recent call last):
  File "D:\wzhData\app\conda3\envs\DataAnalysis_39\lib\site-packages\flask\app.py", line 1473, in wsgi_app
    response = self.full_dispatch_request()
  File "D:\wzhData\app\conda3\envs\DataAnalysis_39\lib\site-packages\flask\app.py", line 882, in full_dispatch_request
    rv = self.handle_user_exception(e)
  File "D:\wzhData\app\conda3\envs\DataAnalysis_39\lib\site-packages\flask_cors\extension.py", line 178, in wrapped_function
    return cors_after_request(app.make_response(f(*args, **kwargs)))
  File "D:\wzhData\app\conda3\envs\DataAnalysis_39\lib\site-packages\flask\app.py", line 880, in full_dispatch_request
    rv = self.dispatch_request()
  File "D:\wzhData\app\conda3\envs\DataAnalysis_39\lib\site-packages\flask\app.py", line 865, in dispatch_request
    return self.ensure_sync(self.view_functions[rule.endpoint])(**view_args)  # type: ignore[no-any-return]
  File "D:\wzhData\BaiduSyncdisk\project\python\Influencer_Data_Management_System\spider\spider_notice.py", line 89, in post_spider_notice
    isSuccess, last_message = spider_notice.get_finish_notice(return_id)
  File "D:\wzhData\BaiduSyncdisk\project\python\Influencer_Data_Management_System\spider\spider_notice.py", line 71, in get_finish_notice
    self.clean_id_notice(_id)
  File "D:\wzhData\BaiduSyncdisk\project\python\Influencer_Data_Management_System\spider\spider_notice.py", line 38, in clean_id_notice
    del self.notice_info[_id]
KeyError: '71063f53-f084-42d4-a4de-255c58f308f0'
2024-08-09 10:44:00,289 - app - ERROR - Exception on /notice/spider [POST]
Traceback (most recent call last):
  File "D:\wzhData\app\conda3\envs\DataAnalysis_39\lib\site-packages\flask\app.py", line 1473, in wsgi_app
    response = self.full_dispatch_request()
  File "D:\wzhData\app\conda3\envs\DataAnalysis_39\lib\site-packages\flask\app.py", line 882, in full_dispatch_request
    rv = self.handle_user_exception(e)
  File "D:\wzhData\app\conda3\envs\DataAnalysis_39\lib\site-packages\flask_cors\extension.py", line 178, in wrapped_function
    return cors_after_request(app.make_response(f(*args, **kwargs)))
  File "D:\wzhData\app\conda3\envs\DataAnalysis_39\lib\site-packages\flask\app.py", line 880, in full_dispatch_request
    rv = self.dispatch_request()
  File "D:\wzhData\app\conda3\envs\DataAnalysis_39\lib\site-packages\flask\app.py", line 865, in dispatch_request
    return self.ensure_sync(self.view_functions[rule.endpoint])(**view_args)  # type: ignore[no-any-return]
  File "D:\wzhData\BaiduSyncdisk\project\python\Influencer_Data_Management_System\spider\spider_notice.py", line 89, in post_spider_notice
    isSuccess, last_message = spider_notice.get_finish_notice(return_id)
  File "D:\wzhData\BaiduSyncdisk\project\python\Influencer_Data_Management_System\spider\spider_notice.py", line 71, in get_finish_notice
    self.clean_id_notice(_id)
  File "D:\wzhData\BaiduSyncdisk\project\python\Influencer_Data_Management_System\spider\spider_notice.py", line 38, in clean_id_notice
    del self.notice_info[_id]
KeyError: '71063f53-f084-42d4-a4de-255c58f308f0'
2024-08-09 10:44:05,292 - app - ERROR - Exception on /notice/spider [POST]
Traceback (most recent call last):
  File "D:\wzhData\app\conda3\envs\DataAnalysis_39\lib\site-packages\flask\app.py", line 1473, in wsgi_app
    response = self.full_dispatch_request()
  File "D:\wzhData\app\conda3\envs\DataAnalysis_39\lib\site-packages\flask\app.py", line 882, in full_dispatch_request
    rv = self.handle_user_exception(e)
  File "D:\wzhData\app\conda3\envs\DataAnalysis_39\lib\site-packages\flask_cors\extension.py", line 178, in wrapped_function
    return cors_after_request(app.make_response(f(*args, **kwargs)))
  File "D:\wzhData\app\conda3\envs\DataAnalysis_39\lib\site-packages\flask\app.py", line 880, in full_dispatch_request
    rv = self.dispatch_request()
  File "D:\wzhData\app\conda3\envs\DataAnalysis_39\lib\site-packages\flask\app.py", line 865, in dispatch_request
    return self.ensure_sync(self.view_functions[rule.endpoint])(**view_args)  # type: ignore[no-any-return]
  File "D:\wzhData\BaiduSyncdisk\project\python\Influencer_Data_Management_System\spider\spider_notice.py", line 89, in post_spider_notice
    isSuccess, last_message = spider_notice.get_finish_notice(return_id)
  File "D:\wzhData\BaiduSyncdisk\project\python\Influencer_Data_Management_System\spider\spider_notice.py", line 71, in get_finish_notice
    self.clean_id_notice(_id)
  File "D:\wzhData\BaiduSyncdisk\project\python\Influencer_Data_Management_System\spider\spider_notice.py", line 38, in clean_id_notice
    del self.notice_info[_id]
KeyError: '71063f53-f084-42d4-a4de-255c58f308f0'
2024-08-09 10:44:10,283 - app - ERROR - Exception on /notice/spider [POST]
Traceback (most recent call last):
  File "D:\wzhData\app\conda3\envs\DataAnalysis_39\lib\site-packages\flask\app.py", line 1473, in wsgi_app
    response = self.full_dispatch_request()
  File "D:\wzhData\app\conda3\envs\DataAnalysis_39\lib\site-packages\flask\app.py", line 882, in full_dispatch_request
    rv = self.handle_user_exception(e)
  File "D:\wzhData\app\conda3\envs\DataAnalysis_39\lib\site-packages\flask_cors\extension.py", line 178, in wrapped_function
    return cors_after_request(app.make_response(f(*args, **kwargs)))
  File "D:\wzhData\app\conda3\envs\DataAnalysis_39\lib\site-packages\flask\app.py", line 880, in full_dispatch_request
    rv = self.dispatch_request()
  File "D:\wzhData\app\conda3\envs\DataAnalysis_39\lib\site-packages\flask\app.py", line 865, in dispatch_request
    return self.ensure_sync(self.view_functions[rule.endpoint])(**view_args)  # type: ignore[no-any-return]
  File "D:\wzhData\BaiduSyncdisk\project\python\Influencer_Data_Management_System\spider\spider_notice.py", line 89, in post_spider_notice
    isSuccess, last_message = spider_notice.get_finish_notice(return_id)
  File "D:\wzhData\BaiduSyncdisk\project\python\Influencer_Data_Management_System\spider\spider_notice.py", line 71, in get_finish_notice
    self.clean_id_notice(_id)
  File "D:\wzhData\BaiduSyncdisk\project\python\Influencer_Data_Management_System\spider\spider_notice.py", line 38, in clean_id_notice
    del self.notice_info[_id]
KeyError: '71063f53-f084-42d4-a4de-255c58f308f0'
2024-08-09 10:44:15,292 - app - ERROR - Exception on /notice/spider [POST]
Traceback (most recent call last):
  File "D:\wzhData\app\conda3\envs\DataAnalysis_39\lib\site-packages\flask\app.py", line 1473, in wsgi_app
    response = self.full_dispatch_request()
  File "D:\wzhData\app\conda3\envs\DataAnalysis_39\lib\site-packages\flask\app.py", line 882, in full_dispatch_request
    rv = self.handle_user_exception(e)
  File "D:\wzhData\app\conda3\envs\DataAnalysis_39\lib\site-packages\flask_cors\extension.py", line 178, in wrapped_function
    return cors_after_request(app.make_response(f(*args, **kwargs)))
  File "D:\wzhData\app\conda3\envs\DataAnalysis_39\lib\site-packages\flask\app.py", line 880, in full_dispatch_request
    rv = self.dispatch_request()
  File "D:\wzhData\app\conda3\envs\DataAnalysis_39\lib\site-packages\flask\app.py", line 865, in dispatch_request
    return self.ensure_sync(self.view_functions[rule.endpoint])(**view_args)  # type: ignore[no-any-return]
  File "D:\wzhData\BaiduSyncdisk\project\python\Influencer_Data_Management_System\spider\spider_notice.py", line 89, in post_spider_notice
    isSuccess, last_message = spider_notice.get_finish_notice(return_id)
  File "D:\wzhData\BaiduSyncdisk\project\python\Influencer_Data_Management_System\spider\spider_notice.py", line 71, in get_finish_notice
    self.clean_id_notice(_id)
  File "D:\wzhData\BaiduSyncdisk\project\python\Influencer_Data_Management_System\spider\spider_notice.py", line 38, in clean_id_notice
    del self.notice_info[_id]
KeyError: '71063f53-f084-42d4-a4de-255c58f308f0'
2024-08-12 15:31:13,043 - app - ERROR - 获取唯一ID失败: (pymysql.err.OperationalError) (1054, "Unknown column '唯一id' in 'field list'")
[SQL: SELECT 唯一id FROM influencers_video_project_data]
(Background on this error at: https://sqlalche.me/e/20/e3q8)
2024-08-12 15:33:52,086 - app - ERROR - 获取唯一ID失败: (pymysql.err.OperationalError) (1054, "Unknown column '唯一id' in 'field list'")
[SQL: SELECT 唯一id FROM influencers_video_project_data]
(Background on this error at: https://sqlalche.me/e/20/e3q8)
2024-08-12 15:34:10,643 - app - ERROR - 获取唯一ID失败: (pymysql.err.OperationalError) (1054, "Unknown column '唯一id' in 'field list'")
[SQL: SELECT 唯一id FROM influencers_video_project_data]
(Background on this error at: https://sqlalche.me/e/20/e3q8)
2024-08-12 15:42:38,642 - app - ERROR - 获取唯一ID失败: (pymysql.err.OperationalError) (1054, "Unknown column '唯一id' in 'field list'")
[SQL: SELECT 唯一id FROM influencers_video_project_data]
(Background on this error at: https://sqlalche.me/e/20/e3q8)
2024-08-12 15:43:45,180 - app - ERROR - 获取唯一ID失败: (pymysql.err.OperationalError) (1054, "Unknown column '唯一id' in 'field list'")
[SQL: SELECT 唯一id FROM influencers_video_project_data]
(Background on this error at: https://sqlalche.me/e/20/e3q8)
2024-08-12 15:43:55,784 - app - ERROR - 获取唯一ID失败: '唯一id'
2024-08-12 16:18:43,458 - app - ERROR - 获取唯一ID失败: '唯一id'
2024-08-12 16:23:10,073 - app - ERROR - Exception on / [GET]
Traceback (most recent call last):
  File "E:\py_flie\marketing\Influencer_Data_Management_System\Lib\site-packages\flask\app.py", line 1473, in wsgi_app
    response = self.full_dispatch_request()
  File "E:\py_flie\marketing\Influencer_Data_Management_System\Lib\site-packages\flask\app.py", line 882, in full_dispatch_request
    rv = self.handle_user_exception(e)
  File "E:\py_flie\marketing\Influencer_Data_Management_System\Lib\site-packages\flask_cors\extension.py", line 178, in wrapped_function
    return cors_after_request(app.make_response(f(*args, **kwargs)))
  File "E:\py_flie\marketing\Influencer_Data_Management_System\Lib\site-packages\flask\app.py", line 880, in full_dispatch_request
    rv = self.dispatch_request()
  File "E:\py_flie\marketing\Influencer_Data_Management_System\Lib\site-packages\flask\app.py", line 865, in dispatch_request
    return self.ensure_sync(self.view_functions[rule.endpoint])(**view_args)  # type: ignore[no-any-return]
  File "E:\py_flie\marketing\Influencer_Data_Management_System\app.py", line 43, in index
    return render_template('index.html', form=project_form)
  File "E:\py_flie\marketing\Influencer_Data_Management_System\Lib\site-packages\flask\templating.py", line 150, in render_template
    return _render(app, template, context)
  File "E:\py_flie\marketing\Influencer_Data_Management_System\Lib\site-packages\flask\templating.py", line 131, in _render
    rv = template.render(context)
  File "E:\py_flie\marketing\Influencer_Data_Management_System\Lib\site-packages\jinja2\environment.py", line 1304, in render
    self.environment.handle_exception()
  File "E:\py_flie\marketing\Influencer_Data_Management_System\Lib\site-packages\jinja2\environment.py", line 939, in handle_exception
    raise rewrite_traceback_stack(source=source)
  File "E:\py_flie\marketing\Influencer_Data_Management_System\templates\index.html", line 7, in top-level template code
    <link rel="stylesheet" href="{{ url_for('static', filename='css/style.css') }}?v={{ time.time() }}">
  File "E:\py_flie\marketing\Influencer_Data_Management_System\Lib\site-packages\jinja2\environment.py", line 487, in getattr
    return getattr(obj, attribute)
jinja2.exceptions.UndefinedError: 'time' is undefined
2024-08-12 16:23:25,568 - app - ERROR - Exception on / [GET]
Traceback (most recent call last):
  File "E:\py_flie\marketing\Influencer_Data_Management_System\Lib\site-packages\flask\app.py", line 1473, in wsgi_app
    response = self.full_dispatch_request()
  File "E:\py_flie\marketing\Influencer_Data_Management_System\Lib\site-packages\flask\app.py", line 882, in full_dispatch_request
    rv = self.handle_user_exception(e)
  File "E:\py_flie\marketing\Influencer_Data_Management_System\Lib\site-packages\flask_cors\extension.py", line 178, in wrapped_function
    return cors_after_request(app.make_response(f(*args, **kwargs)))
  File "E:\py_flie\marketing\Influencer_Data_Management_System\Lib\site-packages\flask\app.py", line 880, in full_dispatch_request
    rv = self.dispatch_request()
  File "E:\py_flie\marketing\Influencer_Data_Management_System\Lib\site-packages\flask\app.py", line 865, in dispatch_request
    return self.ensure_sync(self.view_functions[rule.endpoint])(**view_args)  # type: ignore[no-any-return]
  File "E:\py_flie\marketing\Influencer_Data_Management_System\app.py", line 43, in index
    return render_template('index.html', form=project_form)
  File "E:\py_flie\marketing\Influencer_Data_Management_System\Lib\site-packages\flask\templating.py", line 150, in render_template
    return _render(app, template, context)
  File "E:\py_flie\marketing\Influencer_Data_Management_System\Lib\site-packages\flask\templating.py", line 131, in _render
    rv = template.render(context)
  File "E:\py_flie\marketing\Influencer_Data_Management_System\Lib\site-packages\jinja2\environment.py", line 1304, in render
    self.environment.handle_exception()
  File "E:\py_flie\marketing\Influencer_Data_Management_System\Lib\site-packages\jinja2\environment.py", line 939, in handle_exception
    raise rewrite_traceback_stack(source=source)
  File "E:\py_flie\marketing\Influencer_Data_Management_System\templates\index.html", line 7, in top-level template code
    <link rel="stylesheet" href="{{ url_for('static', filename='css/style.css') }}?v={{ time.time() }}">
  File "E:\py_flie\marketing\Influencer_Data_Management_System\Lib\site-packages\jinja2\environment.py", line 487, in getattr
    return getattr(obj, attribute)
jinja2.exceptions.UndefinedError: 'time' is undefined
2024-08-12 16:23:43,664 - app - ERROR - Exception on / [GET]
Traceback (most recent call last):
  File "E:\py_flie\marketing\Influencer_Data_Management_System\Lib\site-packages\flask\app.py", line 1473, in wsgi_app
    response = self.full_dispatch_request()
  File "E:\py_flie\marketing\Influencer_Data_Management_System\Lib\site-packages\flask\app.py", line 882, in full_dispatch_request
    rv = self.handle_user_exception(e)
  File "E:\py_flie\marketing\Influencer_Data_Management_System\Lib\site-packages\flask_cors\extension.py", line 178, in wrapped_function
    return cors_after_request(app.make_response(f(*args, **kwargs)))
  File "E:\py_flie\marketing\Influencer_Data_Management_System\Lib\site-packages\flask\app.py", line 880, in full_dispatch_request
    rv = self.dispatch_request()
  File "E:\py_flie\marketing\Influencer_Data_Management_System\Lib\site-packages\flask\app.py", line 865, in dispatch_request
    return self.ensure_sync(self.view_functions[rule.endpoint])(**view_args)  # type: ignore[no-any-return]
  File "E:\py_flie\marketing\Influencer_Data_Management_System\app.py", line 43, in index
    return render_template('index.html', form=project_form)
  File "E:\py_flie\marketing\Influencer_Data_Management_System\Lib\site-packages\flask\templating.py", line 150, in render_template
    return _render(app, template, context)
  File "E:\py_flie\marketing\Influencer_Data_Management_System\Lib\site-packages\flask\templating.py", line 131, in _render
    rv = template.render(context)
  File "E:\py_flie\marketing\Influencer_Data_Management_System\Lib\site-packages\jinja2\environment.py", line 1304, in render
    self.environment.handle_exception()
  File "E:\py_flie\marketing\Influencer_Data_Management_System\Lib\site-packages\jinja2\environment.py", line 939, in handle_exception
    raise rewrite_traceback_stack(source=source)
  File "E:\py_flie\marketing\Influencer_Data_Management_System\templates\index.html", line 7, in top-level template code
    <link rel="stylesheet" href="{{ url_for('static', filename='css/style.css') }}?v={{ time.time() }}">
  File "E:\py_flie\marketing\Influencer_Data_Management_System\Lib\site-packages\jinja2\environment.py", line 487, in getattr
    return getattr(obj, attribute)
jinja2.exceptions.UndefinedError: 'time' is undefined
2024-08-12 17:44:39,957 - app - ERROR - 获取项目信息失败: (pymysql.err.OperationalError) (1054, "Unknown column '负责' in 'field list'")
[SQL: SELECT DISTINCT 项目, 负责 FROM influencers_video_project_data]
(Background on this error at: https://sqlalche.me/e/20/e3q8)
2024-08-12 17:45:04,980 - app - ERROR - 获取项目信息失败: '花费'
2024-08-12 17:45:57,762 - app - ERROR - 获取项目信息失败: '花费'
